Workbook

Sheet Stock Data
A1: Date | B1: APPLE | C1: MICROSOFT | D1: AMAZON,COM | E1: ALPHABET A | F1: JOHNSON & JOHNSON | G1: WALMART | H1: JP MORGAN CHASE & CO. | I1: PROCTER & GAMBLE | J1: INTEL | K1: NVIDIA | L1: WALT DISNEY | M1: PFIZER | N1: NETFLIX | O1: BANK OF AMERICA | P1: EXXON MOBIL | Q1: S&P500 | R1: Risk Free
A2: 43831 | B2: 74.06 | C2: 158.78 | D2: 93.75 | E2: 67.42 | F2: 145.87 | G2: 39.62 | H2: 139.79 | I2: 124.5 | J2: 60.24 | K2: 5.97 | L2: 145.29 | M2: 37.25 | N2: 32.61 | O2: 35.35 | P2: 70.24 | Q2: 3244.67 | R2: 1.76
A3: 43832 | B3: 76.07 | C3: 170.43 | D3: 100.53 | E3: 73.08 | F3: 149.42 | G3: 38.3 | H3: 132.66 | I3: 124.66 | J3: 64.45 | K3: 5.89 | L3: 139.79 | M3: 35.51 | N3: 34.72 | O3: 33 | P3: 61.38 | Q3: 3235.66 | R3: 1.5
A4: 43833 | B4: 70.57 | C4: 165.31 | D4: 95.32 | E4: 67.57 | F4: 134.78 | G4: 35.87 | H4: 116.63 | I4: 113.19 | J4: 55.79 | K4: 6.92 | L4: 119.13 | M4: 32.14 | N4: 37.31 | O4: 28.35 | P4: 52.59 | Q4: 2974.28 | R4: 0.87
A5: 43834 | B5: 61.63 | C5: 153 | D5: 96.65 | E5: 56.2 | F5: 127.7 | G5: 37.38 | H5: 85.1 | I5: 107.95 | J5: 52.5 | K5: 6.39 | L5: 93.5 | M5: 30.26 | N5: 37.6 | O5: 19.93 | P5: 36.86 | Q5: 2498.08 | R5: 0.66
A6: 43835 | B6: 71.56 | C6: 175.8 | D6: 116.84 | E6: 66.2 | F6: 149.62 | G6: 40.49 | H6: 93.5 | I6: 117.6 | J6: 58.83 | K6: 7.11 | L6: 106.36 | M6: 35.88 | N6: 41.51 | O6: 23.38 | P6: 45.63 | Q6: 2869.09 | R6: 0.67
A7: 43836 | B7: 79.44 | C7: 182.54 | D7: 122.4 | E7: 71.29 | F7: 147.29 | G7: 41.15 | H7: 97.75 | I7: 116 | J7: 62.49 | K7: 8.83 | L7: 117.26 | M7: 33.65 | N7: 41.88 | O7: 24.28 | P7: 45.32 | Q7: 3038.78 | R7: 0.73
A8: 43837 | B8: 91.28 | C8: 203.14 | D8: 137.9 | E8: 70.96 | F8: 140.69 | G8: 39.82 | H8: 94.89 | I8: 119.65 | J8: 59.91 | K8: 9.52 | L8: 112.82 | M8: 32.74 | N8: 45.4 | O8: 24.03 | P8: 44.49 | Q8: 3105.92 | R8: 0.62
A9: 43838 | B9: 108.2 | C9: 211.52 | D9: 159.03 | E9: 74.55 | F9: 146.39 | G9: 43.3 | H9: 97.02 | I9: 130.47 | J9: 48.27 | K9: 10.73 | L9: 116.17 | M9: 36.6 | N9: 49.09 | O9: 25.03 | P9: 42.05 | Q9: 3288.26 | R9: 0.65
A10: 43839 | B10: 132.76 | C10: 225.51 | D10: 174.48 | E10: 81.61 | F10: 153.87 | G10: 47.07 | H10: 99.55 | I10: 137.86 | J10: 50.91 | K10: 13.48 | L10: 131.92 | M10: 35.82 | N10: 53.26 | O10: 25.58 | P10: 39.75 | Q10: 3507.44 | R10: 0.68
A11: 43840 | B11: 117.64 | C11: 213.49 | D11: 160.4 | E11: 74.18 | F11: 149.31 | G11: 46.93 | H11: 97.12 | I11: 139.58 | J11: 52.4 | K11: 13.76 | L11: 124.94 | M11: 34.99 | N11: 50.6 | O11: 24.27 | P11: 33.79 | Q11: 3385.87 | R11: 0.79
A12: 43841 | B12: 109.11 | C12: 204.29 | D12: 153.09 | E12: 81.18 | F12: 138.98 | G12: 46.86 | H12: 99.39 | I12: 138.51 | J12: 44.96 | K12: 12.66 | L12: 122.24 | M12: 34.06 | N12: 47.89 | O12: 23.89 | P12: 33.14 | Q12: 3296.2 | R12: 0.87
A13: 43842 | B13: 121.01 | C13: 214.51 | D13: 159.43 | E13: 88.33 | F13: 146.29 | G13: 51.2 | H13: 120.34 | I13: 139.16 | J13: 48.75 | K13: 13.49 | L13: 149.57 | M13: 39.4 | N13: 49.23 | O13: 28.74 | P13: 38.96 | Q13: 3645.87 | R13: 0.93
... A74: 46023 | B74: 272.26 | C74: 484.39 | D74: 231.34 | E74: 316.9 | F74: 206.82 | G74: 111.43 | H74: 322.5 | I74: 143.11 | J74: 37.77 | K74: 189.84 | L74: 113.44 | M74: 24.98 | N74: 94.13 | O74: 55.03 | P74: 120.09 | Q74: 6878.11 | R74: 4.15

Sheet Returns
A1: ='Stock Data'!A1 -> Date | B1: ='Stock Data'!B1 -> APPLE | C1: ='Stock Data'!C1 -> MICROSOFT | D1: ='Stock Data'!D1 -> AMAZON,COM | E1: ='Stock Data'!E1 -> ALPHABET A | F1: ='Stock Data'!F1 -> JOHNSON & JOHNSON | G1: ='Stock Data'!G1 -> WALMART | H1: ='Stock Data'!H1 -> JP MORGAN CHASE & CO. | ... R1: ='Stock Data'!R1 -> Risk Free
A2: ='Stock Data'!A2 -> 43831 | R2: ='Stock Data'!R2/(100*12) -> 0.0014666667
A3: ='Stock Data'!A3 -> 43832 | B3: =LOG('Stock Data'!B3)-LOG('Stock Data'!B2) -> 0.011629709 | C3: =LOG('Stock Data'!C3)-LOG('Stock Data'!C2) -> 0.030750246 | D3: =LOG('Stock Data'!D3)-LOG('Stock Data'!D2) -> 0.030324406 | E3: =LOG('Stock Data'!E3)-LOG('Stock Data'!E2) -> 0.03500979 | F3: =LOG('Stock Data'!F3)-LOG('Stock Data'!F2) -> 0.010442749 | G3: =LOG('Stock Data'!G3)-LOG('Stock Data'!G2) -> -0.014715697 | H3: =LOG('Stock Data'!H3)-LOG('Stock Data'!H2) -> -0.022736112 | I3: =LOG('Stock Data'!I3)-LOG('Stock Data'!I2) -> 0.00055777112 | ... Q3: =LOG('Stock Data'!Q3)-LOG('Stock Data'!Q2) -> -0.0012076533 | R3: ='Stock Data'!R3/(100*12) -> 0.00125
A4: ='Stock Data'!A4 -> 43833 | B4: =LOG('Stock Data'!B4)-LOG('Stock Data'!B3) -> -0.032593299 | C4: =LOG('Stock Data'!C4)-LOG('Stock Data'!C3) -> -0.013246918 | D4: =LOG('Stock Data'!D4)-LOG('Stock Data'!D3) -> -0.023111649 | E4: =LOG('Stock Data'!E4)-LOG('Stock Data'!E3) -> -0.03404462 | F4: =LOG('Stock Data'!F4)-LOG('Stock Data'!F3) -> -0.04478328 | G4: =LOG('Stock Data'!G4)-LOG('Stock Data'!G3) -> -0.028467397 | H4: =LOG('Stock Data'!H4)-LOG('Stock Data'!H3) -> -0.055929717 | I4: =LOG('Stock Data'!I4)-LOG('Stock Data'!I3) -> -0.041919063 | ... Q4: =LOG('Stock Data'!Q4)-LOG('Stock Data'!Q3) -> -0.036581029 | R4: ='Stock Data'!R4/(100*12) -> 0.000725
A5: ='Stock Data'!A5 -> 43834 | B5: =LOG('Stock Data'!B5)-LOG('Stock Data'!B4) -> -0.05882795 | C5: =LOG('Stock Data'!C5)-LOG('Stock Data'!C4) -> -0.033607695 | D5: =LOG('Stock Data'!D5)-LOG('Stock Data'!D4) -> 0.0060178247 | E5: =LOG('Stock Data'!E5)-LOG('Stock Data'!E4) -> -0.080017603 | F5: =LOG('Stock Data'!F5)-LOG('Stock Data'!F4) -> -0.023434555 | G5: =LOG('Stock Data'!G5)-LOG('Stock Data'!G4) -> 0.01790792 | H5: =LOG('Stock Data'!H5)-LOG('Stock Data'!H4) -> -0.13688072 | I5: =LOG('Stock Data'!I5)-LOG('Stock Data'!I4) -> -0.020585413 | ... Q5: =LOG('Stock Data'!Q5)-LOG('Stock Data'!Q4) -> -0.075775508 | R5: ='Stock Data'!R5/(100*12) -> 0.00055
A6: ='Stock Data'!A6 -> 43835 | B6: =LOG('Stock Data'!B6)-LOG('Stock Data'!B5) -> 0.064878164 | C6: =LOG('Stock Data'!C6)-LOG('Stock Data'!C5) -> 0.06032744 | D6: =LOG('Stock Data'!D6)-LOG('Stock Data'!D5) -> 0.08238969 | E6: =LOG('Stock Data'!E6)-LOG('Stock Data'!E5) -> 0.071121674 | F6: =LOG('Stock Data'!F6)-LOG('Stock Data'!F5) -> 0.068798753 | G6: =LOG('Stock Data'!G6)-LOG('Stock Data'!G5) -> 0.03470848 | H6: =LOG('Stock Data'!H6)-LOG('Stock Data'!H5) -> 0.040882051 | I6: =LOG('Stock Data'!I6)-LOG('Stock Data'!I5) -> 0.037184675 | ... Q6: =LOG('Stock Data'!Q6)-LOG('Stock Data'!Q5) -> 0.060137829 | R6: ='Stock Data'!R6/(100*12) -> 0.00055833333
A7: ='Stock Data'!A7 -> 43836 | B7: =LOG('Stock Data'!B7)-LOG('Stock Data'!B6) -> 0.045368904 | C7: =LOG('Stock Data'!C7)-LOG('Stock Data'!C6) -> 0.016339175 | D7: =LOG('Stock Data'!D7)-LOG('Stock Data'!D6) -> 0.02018987 | E7: =LOG('Stock Data'!E7)-LOG('Stock Data'!E6) -> 0.032170625 | F7: =LOG('Stock Data'!F7)-LOG('Stock Data'!F6) -> -0.0068163882 | G7: =LOG('Stock Data'!G7)-LOG('Stock Data'!G6) -> 0.0070220628 | H7: =LOG('Stock Data'!H7)-LOG('Stock Data'!H6) -> 0.019305155 | I7: =LOG('Stock Data'!I7)-LOG('Stock Data'!I6) -> -0.0059493325 | ... Q7: =LOG('Stock Data'!Q7)-LOG('Stock Data'!Q6) -> 0.024955088 | R7: ='Stock Data'!R7/(100*12) -> 0.00060833333
A8: ='Stock Data'!A8 -> 43837 | B8: =LOG('Stock Data'!B8)-LOG('Stock Data'!B7) -> 0.060336396 | C8: =LOG('Stock Data'!C8)-LOG('Stock Data'!C7) -> 0.046437402 | D8: =LOG('Stock Data'!D8)-LOG('Stock Data'!D7) -> 0.051782848 | E8: =LOG('Stock Data'!E8)-LOG('Stock Data'!E7) -> -0.0020150079 | F8: =LOG('Stock Data'!F8)-LOG('Stock Data'!F7) -> -0.019910033 | G8: =LOG('Stock Data'!G8)-LOG('Stock Data'!G7) -> -0.014268584 | H8: =LOG('Stock Data'!H8)-LOG('Stock Data'!H7) -> -0.012896319 | I8: =LOG('Stock Data'!I8)-LOG('Stock Data'!I7) -> 0.013454714 | ... Q8: =LOG('Stock Data'!Q8)-LOG('Stock Data'!Q7) -> 0.0094910059 | R8: ='Stock Data'!R8/(100*12) -> 0.00051666667
A9: ='Stock Data'!A9 -> 43838 | B9: =LOG('Stock Data'!B9)-LOG('Stock Data'!B8) -> 0.073851629 | C9: =LOG('Stock Data'!C9)-LOG('Stock Data'!C8) -> 0.01755599 | D9: =LOG('Stock Data'!D9)-LOG('Stock Data'!D8) -> 0.061914793 | E9: =LOG('Stock Data'!E9)-LOG('Stock Data'!E8) -> 0.021434041 | F9: =LOG('Stock Data'!F9)-LOG('Stock Data'!F8) -> 0.017248181 | G9: =LOG('Stock Data'!G9)-LOG('Stock Data'!G8) -> 0.036386641 | H9: =LOG('Stock Data'!H9)-LOG('Stock Data'!H8) -> 0.0096408237 | I9: =LOG('Stock Data'!I9)-LOG('Stock Data'!I8) -> 0.037597959 | ... Q9: =LOG('Stock Data'!Q9)-LOG('Stock Data'!Q8) -> 0.024775884 | R9: ='Stock Data'!R9/(100*12) -> 0.00054166667
A10: ='Stock Data'!A10 -> 43839 | B10: =LOG('Stock Data'!B10)-LOG('Stock Data'!B9) -> 0.088839983 | C10: =LOG('Stock Data'!C10)-LOG('Stock Data'!C9) -> 0.027814367 | D10: =LOG('Stock Data'!D10)-LOG('Stock Data'!D9) -> 0.040266594 | E10: =LOG('Stock Data'!E10)-LOG('Stock Data'!E9) -> 0.03929573 | F10: =LOG('Stock Data'!F10)-LOG('Stock Data'!F9) -> 0.021642543 | G10: =LOG('Stock Data'!G10)-LOG('Stock Data'!G9) -> 0.036256302 | H10: =LOG('Stock Data'!H10)-LOG('Stock Data'!H9) -> 0.011179994 | I10: =LOG('Stock Data'!I10)-LOG('Stock Data'!I9) -> 0.023927612 | ... Q10: =LOG('Stock Data'!Q10)-LOG('Stock Data'!Q9) -> 0.028024101 | R10: ='Stock Data'!R10/(100*12) -> 0.00056666667
A11: ='Stock Data'!A11 -> 43840 | B11: =LOG('Stock Data'!B11)-LOG('Stock Data'!B10) -> -0.052512228 | C11: =LOG('Stock Data'!C11)-LOG('Stock Data'!C10) -> -0.023788268 | D11: =LOG('Stock Data'!D11)-LOG('Stock Data'!D10) -> -0.036541289 | E11: =LOG('Stock Data'!E11)-LOG('Stock Data'!E10) -> -0.041456549 | F11: =LOG('Stock Data'!F11)-LOG('Stock Data'!F10) -> -0.013065058 | G11: =LOG('Stock Data'!G11)-LOG('Stock Data'!G10) -> -0.0012936441 | H11: =LOG('Stock Data'!H11)-LOG('Stock Data'!H10) -> -0.010732591 | I11: =LOG('Stock Data'!I11)-LOG('Stock Data'!I10) -> 0.0053849198 | ... Q11: =LOG('Stock Data'!Q11)-LOG('Stock Data'!Q10) -> -0.015319971 | R11: ='Stock Data'!R11/(100*12) -> 0.00065833333
A12: ='Stock Data'!A12 -> 43841 | B12: =LOG('Stock Data'!B12)-LOG('Stock Data'!B11) -> -0.03269046 | C12: =LOG('Stock Data'!C12)-LOG('Stock Data'!C11) -> -0.019130429 | D12: =LOG('Stock Data'!D12)-LOG('Stock Data'!D11) -> -0.020257541 | E12: =LOG('Stock Data'!E12)-LOG('Stock Data'!E11) -> 0.039162218 | F12: =LOG('Stock Data'!F12)-LOG('Stock Data'!F11) -> -0.031136588 | G12: =LOG('Stock Data'!G12)-LOG('Stock Data'!G11) -> -0.00064826995 | H12: =LOG('Stock Data'!H12)-LOG('Stock Data'!H11) -> 0.010034017 | I12: =LOG('Stock Data'!I12)-LOG('Stock Data'!I11) -> -0.0033420647 | ... Q12: =LOG('Stock Data'!Q12)-LOG('Stock Data'!Q11) -> -0.011656724 | R12: ='Stock Data'!R12/(100*12) -> 0.000725
A13: ='Stock Data'!A13 -> 43842 | B13: =LOG('Stock Data'!B13)-LOG('Stock Data'!B12) -> 0.044956705 | C13: =LOG('Stock Data'!C13)-LOG('Stock Data'!C12) -> 0.021200434 | D13: =LOG('Stock Data'!D13)-LOG('Stock Data'!D12) -> 0.017623223 | E13: =LOG('Stock Data'!E13)-LOG('Stock Data'!E12) -> 0.036659183 | F13: =LOG('Stock Data'!F13)-LOG('Stock Data'!F12) -> 0.022262333 | G13: =LOG('Stock Data'!G13)-LOG('Stock Data'!G12) -> 0.038467677 | H13: =LOG('Stock Data'!H13)-LOG('Stock Data'!H12) -> 0.083067317 | I13: =LOG('Stock Data'!I13)-LOG('Stock Data'!I12) -> 0.0020332908 | ... Q13: =LOG('Stock Data'!Q13)-LOG('Stock Data'!Q12) -> 0.043787624 | R13: ='Stock Data'!R13/(100*12) -> 0.000775
A14: ='Stock Data'!A14 -> 44197 | B14: =LOG('Stock Data'!B14)-LOG('Stock Data'!B13) -> 0.042725063 | C14: =LOG('Stock Data'!C14)-LOG('Stock Data'!C13) -> 0.015941025 | D14: =LOG('Stock Data'!D14)-LOG('Stock Data'!D13) -> 0.010947711 | E14: =LOG('Stock Data'!E14)-LOG('Stock Data'!E13) -> -0.0016255583 | F14: =LOG('Stock Data'!F14)-LOG('Stock Data'!F13) -> 0.031348395 | G14: =LOG('Stock Data'!G14)-LOG('Stock Data'!G13) -> -0.027124885 | H14: =LOG('Stock Data'!H14)-LOG('Stock Data'!H13) -> 0.025100178 | I14: =LOG('Stock Data'!I14)-LOG('Stock Data'!I13) -> 0.0015576176 | ... Q14: =LOG('Stock Data'!Q14)-LOG('Stock Data'!Q13) -> 0.013918812 | R14: ='Stock Data'!R14/(100*12) -> 0.0009
... A74: ='Stock Data'!A74 -> 46023 | B74: =LOG('Stock Data'!B74)-LOG('Stock Data'!B73) -> -0.0090765776 | C74: =LOG('Stock Data'!C74)-LOG('Stock Data'!C73) -> -0.0036071623 | D74: =LOG('Stock Data'!D74)-LOG('Stock Data'!D73) -> -0.0035150598 | E74: =LOG('Stock Data'!E74)-LOG('Stock Data'!E73) -> -0.0010949756 | F74: =LOG('Stock Data'!F74)-LOG('Stock Data'!F73) -> 0.0006724778 | G74: =LOG('Stock Data'!G74)-LOG('Stock Data'!G73) -> 0.0036005516 | H74: =LOG('Stock Data'!H74)-LOG('Stock Data'!H73) -> 0.013054763 | I74: =LOG('Stock Data'!I74)-LOG('Stock Data'!I73) -> -0.014885077 | ... Q74: =LOG('Stock Data'!Q74)-LOG('Stock Data'!Q73) -> 0.0041753519 | R74: ='Stock Data'!R74/(100*12) -> 0.0034583333

Sheet Risk Premia
A1: =Returns!A1 -> Date | B1: =Returns!B1 -> APPLE | C1: =Returns!C1 -> MICROSOFT | D1: =Returns!D1 -> AMAZON,COM | E1: =Returns!E1 -> ALPHABET A | F1: =Returns!F1 -> JOHNSON & JOHNSON | G1: =Returns!G1 -> WALMART | H1: =Returns!H1 -> JP MORGAN CHASE & CO. | ... Q1: =Returns!Q1 -> S&P500
A2: =Returns!A2 -> 43831
A3: =Returns!A3 -> 43832 | B3: =Returns!B3-Returns!$R3 -> 0.010379709 | C3: =Returns!C3-Returns!$R3 -> 0.029500246 | D3: =Returns!D3-Returns!$R3 -> 0.029074406 | E3: =Returns!E3-Returns!$R3 -> 0.03375979 | F3: =Returns!F3-Returns!$R3 -> 0.0091927491 | G3: =Returns!G3-Returns!$R3 -> -0.015965697 | H3: =Returns!H3-Returns!$R3 -> -0.023986112 | I3: =Returns!I3-Returns!$R3 -> -0.00069222888 | ... Q3: =Returns!Q3-Returns!$R3 -> -0.0024576533
A4: =Returns!A4 -> 43833 | B4: =Returns!B4-Returns!$R4 -> -0.033318299 | C4: =Returns!C4-Returns!$R4 -> -0.013971918 | D4: =Returns!D4-Returns!$R4 -> -0.023836649 | E4: =Returns!E4-Returns!$R4 -> -0.03476962 | F4: =Returns!F4-Returns!$R4 -> -0.04550828 | G4: =Returns!G4-Returns!$R4 -> -0.029192397 | H4: =Returns!H4-Returns!$R4 -> -0.056654717 | I4: =Returns!I4-Returns!$R4 -> -0.042644063 | ... Q4: =Returns!Q4-Returns!$R4 -> -0.037306029
A5: =Returns!A5 -> 43834 | B5: =Returns!B5-Returns!$R5 -> -0.05937795 | C5: =Returns!C5-Returns!$R5 -> -0.034157695 | D5: =Returns!D5-Returns!$R5 -> 0.0054678247 | E5: =Returns!E5-Returns!$R5 -> -0.080567603 | F5: =Returns!F5-Returns!$R5 -> -0.023984555 | G5: =Returns!G5-Returns!$R5 -> 0.01735792 | H5: =Returns!H5-Returns!$R5 -> -0.13743072 | I5: =Returns!I5-Returns!$R5 -> -0.021135413 | ... Q5: =Returns!Q5-Returns!$R5 -> -0.076325508
A6: =Returns!A6 -> 43835 | B6: =Returns!B6-Returns!$R6 -> 0.064319831 | C6: =Returns!C6-Returns!$R6 -> 0.059769107 | D6: =Returns!D6-Returns!$R6 -> 0.081831357 | E6: =Returns!E6-Returns!$R6 -> 0.070563341 | F6: =Returns!F6-Returns!$R6 -> 0.06824042 | G6: =Returns!G6-Returns!$R6 -> 0.034150146 | H6: =Returns!H6-Returns!$R6 -> 0.040323717 | I6: =Returns!I6-Returns!$R6 -> 0.036626342 | ... Q6: =Returns!Q6-Returns!$R6 -> 0.059579496
A7: =Returns!A7 -> 43836 | B7: =Returns!B7-Returns!$R7 -> 0.04476057 | C7: =Returns!C7-Returns!$R7 -> 0.015730842 | D7: =Returns!D7-Returns!$R7 -> 0.019581536 | E7: =Returns!E7-Returns!$R7 -> 0.031562292 | F7: =Returns!F7-Returns!$R7 -> -0.0074247216 | G7: =Returns!G7-Returns!$R7 -> 0.0064137294 | H7: =Returns!H7-Returns!$R7 -> 0.018696822 | I7: =Returns!I7-Returns!$R7 -> -0.0065576658 | ... Q7: =Returns!Q7-Returns!$R7 -> 0.024346754
A8: =Returns!A8 -> 43837 | B8: =Returns!B8-Returns!$R8 -> 0.059819729 | C8: =Returns!C8-Returns!$R8 -> 0.045920735 | D8: =Returns!D8-Returns!$R8 -> 0.051266182 | E8: =Returns!E8-Returns!$R8 -> -0.0025316746 | F8: =Returns!F8-Returns!$R8 -> -0.020426699 | G8: =Returns!G8-Returns!$R8 -> -0.014785251 | H8: =Returns!H8-Returns!$R8 -> -0.013412986 | I8: =Returns!I8-Returns!$R8 -> 0.012938047 | ... Q8: =Returns!Q8-Returns!$R8 -> 0.0089743392
A9: =Returns!A9 -> 43838 | B9: =Returns!B9-Returns!$R9 -> 0.073309963 | C9: =Returns!C9-Returns!$R9 -> 0.017014323 | D9: =Returns!D9-Returns!$R9 -> 0.061373126 | E9: =Returns!E9-Returns!$R9 -> 0.020892374 | F9: =Returns!F9-Returns!$R9 -> 0.016706514 | G9: =Returns!G9-Returns!$R9 -> 0.035844974 | H9: =Returns!H9-Returns!$R9 -> 0.009099157 | I9: =Returns!I9-Returns!$R9 -> 0.037056293 | ... Q9: =Returns!Q9-Returns!$R9 -> 0.024234218
A10: =Returns!A10 -> 43839 | B10: =Returns!B10-Returns!$R10 -> 0.088273316 | C10: =Returns!C10-Returns!$R10 -> 0.0272477 | D10: =Returns!D10-Returns!$R10 -> 0.039699927 | E10: =Returns!E10-Returns!$R10 -> 0.038729063 | F10: =Returns!F10-Returns!$R10 -> 0.021075876 | G10: =Returns!G10-Returns!$R10 -> 0.035689635 | H10: =Returns!H10-Returns!$R10 -> 0.010613327 | I10: =Returns!I10-Returns!$R10 -> 0.023360945 | ... Q10: =Returns!Q10-Returns!$R10 -> 0.027457434
A11: =Returns!A11 -> 43840 | B11: =Returns!B11-Returns!$R11 -> -0.053170561 | C11: =Returns!C11-Returns!$R11 -> -0.024446601 | D11: =Returns!D11-Returns!$R11 -> -0.037199622 | E11: =Returns!E11-Returns!$R11 -> -0.042114882 | F11: =Returns!F11-Returns!$R11 -> -0.013723392 | G11: =Returns!G11-Returns!$R11 -> -0.0019519774 | H11: =Returns!H11-Returns!$R11 -> -0.011390924 | I11: =Returns!I11-Returns!$R11 -> 0.0047265865 | ... Q11: =Returns!Q11-Returns!$R11 -> -0.015978304
A12: =Returns!A12 -> 43841 | B12: =Returns!B12-Returns!$R12 -> -0.03341546 | C12: =Returns!C12-Returns!$R12 -> -0.019855429 | D12: =Returns!D12-Returns!$R12 -> -0.020982541 | E12: =Returns!E12-Returns!$R12 -> 0.038437218 | F12: =Returns!F12-Returns!$R12 -> -0.031861588 | G12: =Returns!G12-Returns!$R12 -> -0.00137327 | H12: =Returns!H12-Returns!$R12 -> 0.0093090169 | I12: =Returns!I12-Returns!$R12 -> -0.0040670647 | ... Q12: =Returns!Q12-Returns!$R12 -> -0.012381724
A13: =Returns!A13 -> 43842 | B13: =Returns!B13-Returns!$R13 -> 0.044181705 | C13: =Returns!C13-Returns!$R13 -> 0.020425434 | D13: =Returns!D13-Returns!$R13 -> 0.016848223 | E13: =Returns!E13-Returns!$R13 -> 0.035884183 | F13: =Returns!F13-Returns!$R13 -> 0.021487333 | G13: =Returns!G13-Returns!$R13 -> 0.037692677 | H13: =Returns!H13-Returns!$R13 -> 0.082292317 | I13: =Returns!I13-Returns!$R13 -> 0.0012582908 | ... Q13: =Returns!Q13-Returns!$R13 -> 0.043012624
A14: =Returns!A14 -> 44197 | B14: =Returns!B14-Returns!$R14 -> 0.041825063 | C14: =Returns!C14-Returns!$R14 -> 0.015041025 | D14: =Returns!D14-Returns!$R14 -> 0.010047711 | E14: =Returns!E14-Returns!$R14 -> -0.0025255583 | F14: =Returns!F14-Returns!$R14 -> 0.030448395 | G14: =Returns!G14-Returns!$R14 -> -0.028024885 | H14: =Returns!H14-Returns!$R14 -> 0.024200178 | I14: =Returns!I14-Returns!$R14 -> 0.00065761763 | ... Q14: =Returns!Q14-Returns!$R14 -> 0.013018812
... A74: =Returns!A74 -> 46023 | B74: =Returns!B74-Returns!$R74 -> -0.012534911 | C74: =Returns!C74-Returns!$R74 -> -0.0070654956 | D74: =Returns!D74-Returns!$R74 -> -0.0069733931 | E74: =Returns!E74-Returns!$R74 -> -0.004553309 | F74: =Returns!F74-Returns!$R74 -> -0.0027858555 | G74: =Returns!G74-Returns!$R74 -> 0.00014221827 | H74: =Returns!H74-Returns!$R74 -> 0.0095964297 | I74: =Returns!I74-Returns!$R74 -> -0.01834341 | ... Q74: =Returns!Q74-Returns!$R74 -> 0.00071701861

Sheet Data
B3: ='Risk Premia'!B1 -> APPLE | C3: ='Risk Premia'!C1 -> MICROSOFT | D3: ='Risk Premia'!D1 -> AMAZON,COM | E3: ='Risk Premia'!E1 -> ALPHABET A | F3: ='Risk Premia'!F1 -> JOHNSON & JOHNSON | G3: ='Risk Premia'!G1 -> WALMART | H3: ='Risk Premia'!H1 -> JP MORGAN CHASE & CO. | I3: ='Risk Premia'!I1 -> PROCTER & GAMBLE | ... P3: ='Risk Premia'!P1 -> EXXON MOBIL
A4: Risk Premia | B4: =AVERAGE('Risk Premia'!B2:B74) -> 0.005363775 | C4: =AVERAGE('Risk Premia'!C2:C74) -> 0.0042387644 | D4: =AVERAGE('Risk Premia'!D2:D74) -> 0.0029593211 | E4: =AVERAGE('Risk Premia'!E2:E74) -> 0.0068461827 | F4: =AVERAGE('Risk Premia'!F2:F74) -> -0.00038308031 | G4: =AVERAGE('Risk Premia'!G2:G74) -> 0.003748324 | H4: =AVERAGE('Risk Premia'!H2:H74) -> 0.0025534067 | I4: =AVERAGE('Risk Premia'!I2:I74) -> -0.0016487181 | ... P4: =AVERAGE('Risk Premia'!P2:P74) -> 0.0007460279
A5: ST.DEV | B5: =_xlfn.STDEV.S('Risk Premia'!B2:B74) -> 0.035494017 | C5: =_xlfn.STDEV.S('Risk Premia'!C2:C74) -> 0.027099577 | D5: =_xlfn.STDEV.S('Risk Premia'!D2:D74) -> 0.038732743 | E5: =_xlfn.STDEV.S('Risk Premia'!E2:E74) -> 0.035633772 | F5: =_xlfn.STDEV.S('Risk Premia'!F2:F74) -> 0.021755648 | G5: =_xlfn.STDEV.S('Risk Premia'!G2:G74) -> 0.024356048 | H5: =_xlfn.STDEV.S('Risk Premia'!H2:H74) -> 0.034322679 | I5: =_xlfn.STDEV.S('Risk Premia'!I2:I74) -> 0.021382365 | ... P5: =_xlfn.STDEV.S('Risk Premia'!P2:P74) -> 0.040089663
A6: Variance | B6: =B5^2 -> 0.0012598252 | C6: =C5^2 -> 0.00073438706 | D6: =D5^2 -> 0.0015002254 | E6: =E5^2 -> 0.0012697657 | F6: =F5^2 -> 0.00047330821 | G6: =G5^2 -> 0.00059321708 | H6: =H5^2 -> 0.0011780463 | I6: =I5^2 -> 0.00045720554 | ... P6: =P5^2 -> 0.0016071811
A7: Beta | B7: =_xlfn.COVARIANCE.S('Risk Premia'!B3:B74,'Risk Premia'!$Q$3:$Q$74)/_xlfn.VAR.S('Risk Premia'!$Q$3:$Q$74) -> 1.1863629 | C7: =_xlfn.COVARIANCE.S('Risk Premia'!C3:C74,'Risk Premia'!$Q$3:$Q$74)/_xlfn.VAR.S('Risk Premia'!$Q$3:$Q$74) -> 0.85442636 | D7: =_xlfn.COVARIANCE.S('Risk Premia'!D3:D74,'Risk Premia'!$Q$3:$Q$74)/_xlfn.VAR.S('Risk Premia'!$Q$3:$Q$74) -> 1.0615343 | E7: =_xlfn.COVARIANCE.S('Risk Premia'!E3:E74,'Risk Premia'!$Q$3:$Q$74)/_xlfn.VAR.S('Risk Premia'!$Q$3:$Q$74) -> 1.0497088 | F7: =_xlfn.COVARIANCE.S('Risk Premia'!F3:F74,'Risk Premia'!$Q$3:$Q$74)/_xlfn.VAR.S('Risk Premia'!$Q$3:$Q$74) -> 0.46469886 | G7: =_xlfn.COVARIANCE.S('Risk Premia'!G3:G74,'Risk Premia'!$Q$3:$Q$74)/_xlfn.VAR.S('Risk Premia'!$Q$3:$Q$74) -> 0.47805734 | H7: =_xlfn.COVARIANCE.S('Risk Premia'!H3:H74,'Risk Premia'!$Q$3:$Q$74)/_xlfn.VAR.S('Risk Premia'!$Q$3:$Q$74) -> 1.1550995 | I7: =_xlfn.COVARIANCE.S('Risk Premia'!I3:I74,'Risk Premia'!$Q$3:$Q$74)/_xlfn.VAR.S('Risk Premia'!$Q$3:$Q$74) -> 0.39194601 | ... P7: =_xlfn.COVARIANCE.S('Risk Premia'!P3:P74,'Risk Premia'!$Q$3:$Q$74)/_xlfn.VAR.S('Risk Premia'!$Q$3:$Q$74) -> 0.81172643

Sheet MVO
B2: Covariance Matrix | T2: Return Matrix
B3: =_xlfn.COVARIANCE.S('Risk Premia'!$B$3:$B$74,'Risk Premia'!B3:B74) -> 0.0012598252 | C3: =_xlfn.COVARIANCE.S('Risk Premia'!$B$3:$B$74,'Risk Premia'!C3:C74) -> 0.0005719458 | D3: =_xlfn.COVARIANCE.S('Risk Premia'!$B$3:$B$74,'Risk Premia'!D3:D74) -> 0.00083452599 | E3: =_xlfn.COVARIANCE.S('Risk Premia'!$B$3:$B$74,'Risk Premia'!E3:E74) -> 0.00065839478 | F3: =_xlfn.COVARIANCE.S('Risk Premia'!$B$3:$B$74,'Risk Premia'!F3:F74) -> 0.00029237959 | G3: =_xlfn.COVARIANCE.S('Risk Premia'!$B$3:$B$74,'Risk Premia'!G3:G74) -> 0.00030888847 | H3: =_xlfn.COVARIANCE.S('Risk Premia'!$B$3:$B$74,'Risk Premia'!H3:H74) -> 0.00040687346 | I3: =_xlfn.COVARIANCE.S('Risk Premia'!$B$3:$B$74,'Risk Premia'!I3:I74) -> 0.00026025226 | ... P3: =_xlfn.COVARIANCE.S('Risk Premia'!$B$3:$B$74,'Risk Premia'!P3:P74) -> 0.00028552399 | T3: 0.005363775
B4: {=TRANSPOSE(C3:P3)} -> 0.0005719458 | C4: =_xlfn.COVARIANCE.S('Risk Premia'!$C$3:$C$74,'Risk Premia'!C3:C74) -> 0.00073438706 | D4: =_xlfn.COVARIANCE.S('Risk Premia'!$C$3:$C$74,'Risk Premia'!D3:D74) -> 0.00064713108 | E4: =_xlfn.COVARIANCE.S('Risk Premia'!$C$3:$C$74,'Risk Premia'!E3:E74) -> 0.00054717917 | F4: =_xlfn.COVARIANCE.S('Risk Premia'!$C$3:$C$74,'Risk Premia'!F3:F74) -> 0.00012339619 | G4: =_xlfn.COVARIANCE.S('Risk Premia'!$C$3:$C$74,'Risk Premia'!G3:G74) -> 0.00020982518 | H4: =_xlfn.COVARIANCE.S('Risk Premia'!$C$3:$C$74,'Risk Premia'!H3:H74) -> 0.00030398775 | I4: =_xlfn.COVARIANCE.S('Risk Premia'!$C$3:$C$74,'Risk Premia'!I3:I74) -> 0.00015118663 | J4: =_xlfn.COVARIANCE.S('Risk Premia'!$C$3:$C$74,'Risk Premia'!J3:J74) -> 0.00042255681 | ... P4: =_xlfn.COVARIANCE.S('Risk Premia'!$C$3:$C$74,'Risk Premia'!P3:P74) -> 8.2661691e-05 | T4: 0.0042387644
B5: 0.00083452599 | C5: {=TRANSPOSE(D4:P4)} -> 0.00064713108 | D5: =_xlfn.COVARIANCE.S('Risk Premia'!$D$3:$D$74,'Risk Premia'!D3:D74) -> 0.0015002254 | E5: =_xlfn.COVARIANCE.S('Risk Premia'!$D$3:$D$74,'Risk Premia'!E3:E74) -> 0.00084987816 | F5: =_xlfn.COVARIANCE.S('Risk Premia'!$D$3:$D$74,'Risk Premia'!F3:F74) -> 3.0041924e-05 | G5: =_xlfn.COVARIANCE.S('Risk Premia'!$D$3:$D$74,'Risk Premia'!G3:G74) -> 0.00020083458 | H5: =_xlfn.COVARIANCE.S('Risk Premia'!$D$3:$D$74,'Risk Premia'!H3:H74) -> 0.00029532843 | I5: =_xlfn.COVARIANCE.S('Risk Premia'!$D$3:$D$74,'Risk Premia'!I3:I74) -> 1.179667e-05 | J5: =_xlfn.COVARIANCE.S('Risk Premia'!$D$3:$D$74,'Risk Premia'!J3:J74) -> 0.00052061922 | K5: =_xlfn.COVARIANCE.S('Risk Premia'!$D$3:$D$74,'Risk Premia'!K3:K74) -> 0.0015022558 | ... P5: =_xlfn.COVARIANCE.S('Risk Premia'!$D$3:$D$74,'Risk Premia'!P3:P74) -> 1.0937616e-05 | T5: 0.0029593211
B6: 0.00065839478 | C6: 0.00054717917 | D6: {=TRANSPOSE(E5:P5)} -> 0.00084987816 | E6: =_xlfn.COVARIANCE.S('Risk Premia'!$E$3:$E$74,'Risk Premia'!E3:E74) -> 0.0012697657 | F6: =_xlfn.COVARIANCE.S('Risk Premia'!$E$3:$E$74,'Risk Premia'!F3:F74) -> 0.00015749452 | G6: =_xlfn.COVARIANCE.S('Risk Premia'!$E$3:$E$74,'Risk Premia'!G3:G74) -> 0.00018173004 | H6: =_xlfn.COVARIANCE.S('Risk Premia'!$E$3:$E$74,'Risk Premia'!H3:H74) -> 0.00050688373 | I6: =_xlfn.COVARIANCE.S('Risk Premia'!$E$3:$E$74,'Risk Premia'!I3:I74) -> 3.5346072e-05 | J6: =_xlfn.COVARIANCE.S('Risk Premia'!$E$3:$E$74,'Risk Premia'!J3:J74) -> 0.0005481717 | K6: =_xlfn.COVARIANCE.S('Risk Premia'!$E$3:$E$74,'Risk Premia'!K3:K74) -> 0.0010031743 | L6: =_xlfn.COVARIANCE.S('Risk Premia'!$E$3:$E$74,'Risk Premia'!L3:L74) -> 0.00060693836 | ... P6: =_xlfn.COVARIANCE.S('Risk Premia'!$E$3:$E$74,'Risk Premia'!P3:P74) -> 0.00030189691 | T6: 0.0068461827
B7: 0.00029237959 | C7: 0.00012339619 | D7: 3.0041924e-05 | E7: {=TRANSPOSE(F6:P6)} -> 0.00015749452 | F7: =_xlfn.COVARIANCE.S('Risk Premia'!$F$3:$F$74,'Risk Premia'!F3:F74) -> 0.00047330821 | G7: =_xlfn.COVARIANCE.S('Risk Premia'!$F$3:$F$74,'Risk Premia'!G3:G74) -> 0.00018995367 | H7: =_xlfn.COVARIANCE.S('Risk Premia'!$F$3:$F$74,'Risk Premia'!H3:H74) -> 0.00026956129 | I7: =_xlfn.COVARIANCE.S('Risk Premia'!$F$3:$F$74,'Risk Premia'!I3:I74) -> 0.00020124523 | J7: =_xlfn.COVARIANCE.S('Risk Premia'!$F$3:$F$74,'Risk Premia'!J3:J74) -> 0.00040351694 | K7: =_xlfn.COVARIANCE.S('Risk Premia'!$F$3:$F$74,'Risk Premia'!K3:K74) -> -4.2322197e-05 | L7: =_xlfn.COVARIANCE.S('Risk Premia'!$F$3:$F$74,'Risk Premia'!L3:L74) -> 0.00021104773 | M7: =_xlfn.COVARIANCE.S('Risk Premia'!$F$3:$F$74,'Risk Premia'!M3:M74) -> 0.00033971805 | ... P7: =_xlfn.COVARIANCE.S('Risk Premia'!$F$3:$F$74,'Risk Premia'!P3:P74) -> 0.00029087179 | T7: -0.00038308031
B8: 0.00030888847 | C8: 0.00020982518 | D8: 0.00020083458 | E8: 0.00018173004 | F8: {=TRANSPOSE(G7:P7)} -> 0.00018995367 | G8: =_xlfn.COVARIANCE.S('Risk Premia'!$G$3:$G$74,'Risk Premia'!G3:G74) -> 0.00059321708 | H8: =_xlfn.COVARIANCE.S('Risk Premia'!$G$3:$G$74,'Risk Premia'!H3:H74) -> 0.00018685512 | I8: =_xlfn.COVARIANCE.S('Risk Premia'!$G$3:$G$74,'Risk Premia'!I3:I74) -> 0.00024595088 | J8: =_xlfn.COVARIANCE.S('Risk Premia'!$G$3:$G$74,'Risk Premia'!J3:J74) -> 5.8677416e-05 | K8: =_xlfn.COVARIANCE.S('Risk Premia'!$G$3:$G$74,'Risk Premia'!K3:K74) -> 0.00030077381 | L8: =_xlfn.COVARIANCE.S('Risk Premia'!$G$3:$G$74,'Risk Premia'!L3:L74) -> 0.00025846334 | M8: =_xlfn.COVARIANCE.S('Risk Premia'!$G$3:$G$74,'Risk Premia'!M3:M74) -> 0.00015178596 | N8: =_xlfn.COVARIANCE.S('Risk Premia'!$G$3:$G$74,'Risk Premia'!N3:N74) -> 0.00031286429 | ... P8: =_xlfn.COVARIANCE.S('Risk Premia'!$G$3:$G$74,'Risk Premia'!P3:P74) -> -1.636752e-05 | T8: 0.003748324
B9: 0.00040687346 | C9: 0.00030398775 | D9: 0.00029532843 | E9: 0.00050688373 | F9: 0.00026956129 | G9: {=TRANSPOSE(H8:P8)} -> 0.00018685512 | H9: =_xlfn.COVARIANCE.S('Risk Premia'!$H$3:$H$74,'Risk Premia'!H3:H74) -> 0.0011780463 | I9: =_xlfn.COVARIANCE.S('Risk Premia'!$H$3:$H$74,'Risk Premia'!I3:I74) -> 0.0001538424 | J9: =_xlfn.COVARIANCE.S('Risk Premia'!$H$3:$H$74,'Risk Premia'!J3:J74) -> 0.00056920691 | K9: =_xlfn.COVARIANCE.S('Risk Premia'!$H$3:$H$74,'Risk Premia'!K3:K74) -> 0.00068894004 | L9: =_xlfn.COVARIANCE.S('Risk Premia'!$H$3:$H$74,'Risk Premia'!L3:L74) -> 0.0010290555 | M9: =_xlfn.COVARIANCE.S('Risk Premia'!$H$3:$H$74,'Risk Premia'!M3:M74) -> 0.00028851265 | N9: =_xlfn.COVARIANCE.S('Risk Premia'!$H$3:$H$74,'Risk Premia'!N3:N74) -> 0.00070912226 | O9: =_xlfn.COVARIANCE.S('Risk Premia'!$H$3:$H$74,'Risk Premia'!O3:O74) -> 0.0012416637 | P9: =_xlfn.COVARIANCE.S('Risk Premia'!$H$3:$H$74,'Risk Premia'!P3:P74) -> 0.0007711898 | T9: 0.0025534067
B10: 0.00026025226 | C10: 0.00015118663 | D10: 1.179667e-05 | E10: 3.5346072e-05 | F10: 0.00020124523 | G10: 0.00024595088 | H10: {=TRANSPOSE(I9:P9)} -> 0.0001538424 | I10: =_xlfn.COVARIANCE.S('Risk Premia'!$I$3:$I$74,'Risk Premia'!I3:I74) -> 0.00045720554 | J10: =_xlfn.COVARIANCE.S('Risk Premia'!$I$3:$I$74,'Risk Premia'!J3:J74) -> 0.00014380341 | K10: =_xlfn.COVARIANCE.S('Risk Premia'!$I$3:$I$74,'Risk Premia'!K3:K74) -> 5.3778033e-05 | L10: =_xlfn.COVARIANCE.S('Risk Premia'!$I$3:$I$74,'Risk Premia'!L3:L74) -> 0.00026472775 | M10: =_xlfn.COVARIANCE.S('Risk Premia'!$I$3:$I$74,'Risk Premia'!M3:M74) -> 0.0001949422 | N10: =_xlfn.COVARIANCE.S('Risk Premia'!$I$3:$I$74,'Risk Premia'!N3:N74) -> 1.5832417e-05 | O10: =_xlfn.COVARIANCE.S('Risk Premia'!$I$3:$I$74,'Risk Premia'!O3:O74) -> 0.00021492915 | P10: =_xlfn.COVARIANCE.S('Risk Premia'!$I$3:$I$74,'Risk Premia'!P3:P74) -> 0.00010285005 | T10: -0.0016487181
B11: 0.00068566129 | C11: 0.00042255681 | D11: 0.00052061922 | E11: 0.0005481717 | F11: 0.00040351694 | G11: 5.8677416e-05 | H11: 0.00056920691 | I11: {=TRANSPOSE(J10:P10)} -> 0.00014380341 | J11: =_xlfn.COVARIANCE.S('Risk Premia'!$J$3:$J$74,'Risk Premia'!J3:J74) -> 0.0029995926 | K11: =_xlfn.COVARIANCE.S('Risk Premia'!$J$3:$J$74,'Risk Premia'!K3:K74) -> 0.0010139577 | L11: =_xlfn.COVARIANCE.S('Risk Premia'!$J$3:$J$74,'Risk Premia'!L3:L74) -> 0.00084190829 | M11: =_xlfn.COVARIANCE.S('Risk Premia'!$J$3:$J$74,'Risk Premia'!M3:M74) -> 0.00037673116 | N11: =_xlfn.COVARIANCE.S('Risk Premia'!$J$3:$J$74,'Risk Premia'!N3:N74) -> 0.00058111111 | O11: =_xlfn.COVARIANCE.S('Risk Premia'!$J$3:$J$74,'Risk Premia'!O3:O74) -> 0.00068843664 | P11: =_xlfn.COVARIANCE.S('Risk Premia'!$J$3:$J$74,'Risk Premia'!P3:P74) -> 0.00048742566 | T11: -0.0053048099
B12: 0.0011574874 | C12: 0.0010727784 | D12: 0.0015022558 | E12: 0.0010031743 | F12: -4.2322197e-05 | G12: 0.00030077381 | H12: 0.00068894004 | I12: 5.3778033e-05 | J12: {=TRANSPOSE(K11:P11)} -> 0.0010139577 | K12: =_xlfn.COVARIANCE.S('Risk Premia'!$K$3:$K$74,'Risk Premia'!K3:K74) -> 0.0036983186 | L12: =_xlfn.COVARIANCE.S('Risk Premia'!$K$3:$K$74,'Risk Premia'!L3:L74) -> 0.00091792575 | M12: =_xlfn.COVARIANCE.S('Risk Premia'!$K$3:$K$74,'Risk Premia'!M3:M74) -> 0.00037240807 | N12: =_xlfn.COVARIANCE.S('Risk Premia'!$K$3:$K$74,'Risk Premia'!N3:N74) -> 0.0019537625 | O12: =_xlfn.COVARIANCE.S('Risk Premia'!$K$3:$K$74,'Risk Premia'!O3:O74) -> 0.0008455402 | P12: =_xlfn.COVARIANCE.S('Risk Premia'!$K$3:$K$74,'Risk Premia'!P3:P74) -> 9.3490871e-05 | T12: 0.018377848
B13: 0.00069438778 | C13: 0.00046511933 | D13: 0.00080328039 | E13: 0.00060693836 | F13: 0.00021104773 | G13: 0.00025846334 | H13: 0.0010290555 | I13: 0.00026472775 | J13: 0.00084190829 | K13: {=TRANSPOSE(L12:P12)} -> 0.00091792575 | L13: =_xlfn.COVARIANCE.S('Risk Premia'!$L$3:$L$74,'Risk Premia'!L3:L74) -> 0.001901819 | M13: =_xlfn.COVARIANCE.S('Risk Premia'!$L$3:$L$74,'Risk Premia'!M3:M74) -> 4.5204448e-05 | N13: =_xlfn.COVARIANCE.S('Risk Premia'!$L$3:$L$74,'Risk Premia'!N3:N74) -> 0.00099441796 | O13: =_xlfn.COVARIANCE.S('Risk Premia'!$L$3:$L$74,'Risk Premia'!O3:O74) -> 0.0012325188 | P13: =_xlfn.COVARIANCE.S('Risk Premia'!$L$3:$L$74,'Risk Premia'!P3:P74) -> 0.0007636251 | T13: -0.0039816367
B14: 0.00042339975 | C14: 0.00020982753 | D14: 0.00017743715 | E14: 0.00034561643 | F14: 0.00033971805 | G14: 0.00015178596 | H14: 0.00028851265 | I14: 0.0001949422 | J14: 0.00037673116 | K14: 0.00037240807 | L14: {=TRANSPOSE(M13:P13)} -> 4.5204448e-05 | M14: =_xlfn.COVARIANCE.S('Risk Premia'!$M$3:$M$74,'Risk Premia'!M3:M74) -> 0.0009591645 | N14: =_xlfn.COVARIANCE.S('Risk Premia'!$M$3:$M$74,'Risk Premia'!N3:N74) -> 0.0002022899 | O14: =_xlfn.COVARIANCE.S('Risk Premia'!$M$3:$M$74,'Risk Premia'!O3:O74) -> 0.00030786883 | P14: =_xlfn.COVARIANCE.S('Risk Premia'!$M$3:$M$74,'Risk Premia'!P3:P74) -> 0.00019726529 | T14: -0.0048991969
B15: 0.00075567814 | C15: 0.00078511999 | D15: 0.0012895208 | E15: 0.00070487096 | F15: -4.3585704e-05 | G15: 0.00031286429 | H15: 0.00070912226 | I15: 1.5832417e-05 | J15: 0.00058111111 | K15: 0.0019537625 | L15: 0.00099441796 | M15: {=TRANSPOSE(N14:P14)} -> 0.0002022899 | N15: =_xlfn.COVARIANCE.S('Risk Premia'!$N$3:$N$74,'Risk Premia'!N3:N74) -> 0.0030305004 | O15: =_xlfn.COVARIANCE.S('Risk Premia'!$N$3:$N$74,'Risk Premia'!O3:O74) -> 0.00075301058 | P15: =_xlfn.COVARIANCE.S('Risk Premia'!$N$3:$N$74,'Risk Premia'!P3:P74) -> -0.00016430912 | T15: 0.003905124
B16: 0.0006090514 | C16: 0.00035852566 | D16: 0.00048767075 | E16: 0.00066156873 | F16: 0.00029268536 | G16: 0.00023913072 | H16: 0.0012416637 | I16: 0.00021492915 | J16: 0.00068843664 | K16: 0.0008455402 | L16: 0.0012325188 | M16: 0.00030786883 | N16: {=TRANSPOSE(O15:P15)} -> 0.00075301058 | O16: =_xlfn.COVARIANCE.S('Risk Premia'!$O$3:$O$74,'Risk Premia'!O3:O74) -> 0.0015786927 | P16: =_xlfn.COVARIANCE.S('Risk Premia'!$O$3:$O$74,'Risk Premia'!P3:P74) -> 0.00098683116 | T16: 0.00018058002
B17: 0.00028552399 | C17: 8.2661691e-05 | D17: 1.0937616e-05 | E17: 0.00030189691 | F17: 0.00029087179 | G17: -1.636752e-05 | H17: 0.0007711898 | I17: 0.00010285005 | J17: 0.00048742566 | K17: 9.3490871e-05 | L17: 0.0007636251 | M17: 0.00019726529 | N17: -0.00016430912 | O17: =P16 -> 0.00098683116 | P17: =_xlfn.COVARIANCE.S('Risk Premia'!$P$3:$P$74,'Risk Premia'!P3:P74) -> 0.0016071811 | T17: 0.0007460279
B20: Optimized Matrix | T20: Weight Matrix
B21: =2*B3 -> 0.0025196505 | C21: =2*C3 -> 0.0011438916 | D21: =2*D3 -> 0.001669052 | E21: =2*E3 -> 0.0013167896 | F21: =2*F3 -> 0.00058475918 | G21: =2*G3 -> 0.00061777695 | H21: =2*H3 -> 0.00081374692 | I21: =2*I3 -> 0.00052050451 | ... P21: =2*P3 -> 0.00057104798 | Q21: -1 | R21: -1 | T21: 0
B22: =2*B4 -> 0.0011438916 | C22: =2*C4 -> 0.0014687741 | D22: =2*D4 -> 0.0012942622 | E22: =2*E4 -> 0.0010943583 | F22: =2*F4 -> 0.00024679239 | G22: =2*G4 -> 0.00041965036 | H22: =2*H4 -> 0.00060797549 | I22: =2*I4 -> 0.00030237326 | ... P22: =2*P4 -> 0.00016532338 | Q22: -1 | R22: 0 | T22: 0
B23: =2*B5 -> 0.001669052 | C23: =2*C5 -> 0.0012942622 | D23: =2*D5 -> 0.0030004508 | E23: =2*E5 -> 0.0016997563 | F23: =2*F5 -> 6.0083849e-05 | G23: =2*G5 -> 0.00040166917 | H23: =2*H5 -> 0.00059065686 | I23: =2*I5 -> 2.359334e-05 | ... P23: =2*P5 -> 2.1875233e-05 | Q23: -1 | R23: 0 | T23: 0
B24: =2*B6 -> 0.0013167896 | C24: =2*C6 -> 0.0010943583 | D24: =2*D6 -> 0.0016997563 | E24: =2*E6 -> 0.0025395315 | F24: =2*F6 -> 0.00031498904 | G24: =2*G6 -> 0.00036346008 | H24: =2*H6 -> 0.0010137675 | I24: =2*I6 -> 7.0692144e-05 | ... P24: =2*P6 -> 0.00060379382 | Q24: -1 | R24: 0 | T24: 0
B25: =2*B7 -> 0.00058475918 | C25: =2*C7 -> 0.00024679239 | D25: =2*D7 -> 6.0083849e-05 | E25: =2*E7 -> 0.00031498904 | F25: =2*F7 -> 0.00094661641 | G25: =2*G7 -> 0.00037990733 | H25: =2*H7 -> 0.00053912258 | I25: =2*I7 -> 0.00040249045 | ... P25: =2*P7 -> 0.00058174359 | Q25: -1 | R25: 0 | T25: 0
B26: =2*B8 -> 0.00061777695 | C26: =2*C8 -> 0.00041965036 | D26: =2*D8 -> 0.00040166917 | E26: =2*E8 -> 0.00036346008 | F26: =2*F8 -> 0.00037990733 | G26: =2*G8 -> 0.0011864342 | H26: =2*H8 -> 0.00037371025 | I26: =2*I8 -> 0.00049190177 | ... P26: =2*P8 -> -3.273504e-05 | Q26: -1 | R26: 0 | T26: 0
B27: =2*B9 -> 0.00081374692 | C27: =2*C9 -> 0.00060797549 | D27: =2*D9 -> 0.00059065686 | E27: =2*E9 -> 0.0010137675 | F27: =2*F9 -> 0.00053912258 | G27: =2*G9 -> 0.00037371025 | H27: =2*H9 -> 0.0023560925 | I27: =2*I9 -> 0.00030768481 | ... P27: =2*P9 -> 0.0015423796 | Q27: -1 | R27: 0 | T27: 0
B28: =2*B10 -> 0.00052050451 | C28: =2*C10 -> 0.00030237326 | D28: =2*D10 -> 2.359334e-05 | E28: =2*E10 -> 7.0692144e-05 | F28: =2*F10 -> 0.00040249045 | G28: =2*G10 -> 0.00049190177 | H28: =2*H10 -> 0.00030768481 | I28: =2*I10 -> 0.00091441108 | ... P28: =2*P10 -> 0.0002057001 | Q28: -1 | R28: 0 | T28: 0
B29: =2*B11 -> 0.0013713226 | C29: =2*C11 -> 0.00084511363 | D29: =2*D11 -> 0.0010412384 | E29: =2*E11 -> 0.0010963434 | F29: =2*F11 -> 0.00080703388 | G29: =2*G11 -> 0.00011735483 | H29: =2*H11 -> 0.0011384138 | I29: =2*I11 -> 0.00028760682 | ... P29: =2*P11 -> 0.00097485132 | Q29: -1 | R29: 0 | T29: 0
B30: =2*B12 -> 0.0023149748 | C30: =2*C12 -> 0.0021455569 | D30: =2*D12 -> 0.0030045115 | E30: =2*E12 -> 0.0020063486 | F30: =2*F12 -> -8.4644393e-05 | G30: =2*G12 -> 0.00060154762 | H30: =2*H12 -> 0.0013778801 | I30: =2*I12 -> 0.00010755607 | ... P30: =2*P12 -> 0.00018698174 | Q30: -1 | R30: 0 | T30: 0
B31: =2*B13 -> 0.0013887756 | C31: =2*C13 -> 0.00093023866 | D31: =2*D13 -> 0.0016065608 | E31: =2*E13 -> 0.0012138767 | F31: =2*F13 -> 0.00042209546 | G31: =2*G13 -> 0.00051692668 | H31: =2*H13 -> 0.002058111 | I31: =2*I13 -> 0.0005294555 | ... P31: =2*P13 -> 0.0015272502 | Q31: -1 | R31: 0 | T31: 0
B32: =2*B14 -> 0.0008467995 | C32: =2*C14 -> 0.00041965505 | D32: =2*D14 -> 0.00035487429 | E32: =2*E14 -> 0.00069123287 | F32: =2*F14 -> 0.0006794361 | G32: =2*G14 -> 0.00030357192 | H32: =2*H14 -> 0.00057702531 | I32: =2*I14 -> 0.00038988441 | ... P32: =2*P14 -> 0.00039453058 | Q32: -1 | R32: 0 | T32: 0
... B35: =2*B17 -> 0.00057104798 | C35: =2*C17 -> 0.00016532338 | D35: =2*D17 -> 2.1875233e-05 | E35: =2*E17 -> 0.00060379382 | F35: =2*F17 -> 0.00058174359 | G35: =2*G17 -> -3.273504e-05 | H35: =2*H17 -> 0.0015423796 | I35: =2*I17 -> 0.0002057001 | ... P35: =2*P17 -> 0.0032143622 | Q35: -1 | R35: 0 | T35: 0
B36: 1 | C36: 1 | D36: 1 | E36: 1 | F36: 1 | G36: 1 | H36: 1 | I36: 1 | J36: 1 | K36: 1 | L36: 1 | M36: 1 | N36: 1 | O36: 1 | P36: 1 | Q36: 0 | R36: 0 | T36: 1
B37: 1 | C37: 0 | D37: 0 | E37: 0 | F37: 0 | G37: 0 | H37: 0 | I37: 0 | J37: 0 | K37: 0 | L37: 0 | M37: 0 | N37: 0 | O37: 0 | P37: 0 | Q37: 0 | R37: 0 | T37: 0.1
C39: Optimal Weights | F39: Return | H39: Variance of Portfolio | K39: St.DEV
C40: {=MMULT(MINVERSE(B21:R37),T21:T37)} -> 0.1 | F40: {=MMULT(TRANSPOSE(C40:C54),T3:T17)} -> 0.0021438191 | H40: {=MMULT(TRANSPOSE(C40:C54),MMULT(B3:P17,C40:C54))} -> 0.00023201732 | K40: =SQRT(H40) -> 0.015232115
C41: 0.044445857
C42: 0.17298267
C43: 0.025170121
C44: 0.12365088
C45: 0.1531967
C46: 0.38493045
...
